[32m2024-02-20 14:27:55 +0100[0m - dagster - [34mDEBUG[0m - __ASSET_JOB - 577499b6-cee4-43b8-bd48-a510617ed10a - 18914 - LOGS_CAPTURED - Started capturing logs in process (pid: 18914).
[32m2024-02-20 14:27:55 +0100[0m - dagster - [34mDEBUG[0m - __ASSET_JOB - 577499b6-cee4-43b8-bd48-a510617ed10a - 18914 - versionPrediction - STEP_START - Started execution of step "versionPrediction".
Traceback (most recent call last):
  File "/opt/homebrew/lib/python3.11/site-packages/dvc/cli/__init__.py", line 210, in main
    cmd = args.func(args)
          ^^^^^^^^^^^^^^^
  File "/opt/homebrew/lib/python3.11/site-packages/dvc/cli/command.py", line 17, in __init__
    from dvc.repo import Repo
  File "/opt/homebrew/lib/python3.11/site-packages/dvc/repo/__init__.py", line 14, in <module>
    from dvc.ignore import DvcIgnoreFilter
  File "/opt/homebrew/lib/python3.11/site-packages/dvc/ignore.py", line 11, in <module>
    from dvc.fs import Schemes, localfs
  File "/opt/homebrew/lib/python3.11/site-packages/dvc/fs/__init__.py", line 4, in <module>
    from dvc_http import HTTPFileSystem, HTTPSFileSystem  # noqa: F401
    ^^^^^^^^^^^^^^^^^^^^^^^^^^^^^^^^^^^^^^^^^^^^^^^^^^^^
  File "/opt/homebrew/lib/python3.11/site-packages/dvc_http/__init__.py", line 6, in <module>
    from dvc_objects.fs.base import FileSystem
  File "/opt/homebrew/lib/python3.11/site-packages/dvc_objects/fs/__init__.py", line 5, in <module>
    from . import generic  # noqa: F401
    ^^^^^^^^^^^^^^^^^^^^^
  File "/opt/homebrew/lib/python3.11/site-packages/dvc_objects/fs/generic.py", line 10, in <module>
    from fsspec.callbacks import DEFAULT_CALLBACK
ImportError: cannot import name 'DEFAULT_CALLBACK' from 'fsspec.callbacks' (/opt/homebrew/lib/python3.11/site-packages/fsspec/callbacks.py)

During handling of the above exception, another exception occurred:

Traceback (most recent call last):
  File "/opt/homebrew/bin/dvc", line 8, in <module>
    sys.exit(main())
             ^^^^^^
  File "/opt/homebrew/lib/python3.11/site-packages/dvc/cli/__init__.py", line 236, in main
    ret = _log_exceptions(exc) or 255
          ^^^^^^^^^^^^^^^^^^^^
  File "/opt/homebrew/lib/python3.11/site-packages/dvc/cli/__init__.py", line 77, in _log_exceptions
    from dvc.fs import AuthError, ConfigError, RemoteMissingDepsError
  File "/opt/homebrew/lib/python3.11/site-packages/dvc/fs/__init__.py", line 4, in <module>
    from dvc_http import HTTPFileSystem, HTTPSFileSystem  # noqa: F401
    ^^^^^^^^^^^^^^^^^^^^^^^^^^^^^^^^^^^^^^^^^^^^^^^^^^^^
  File "/opt/homebrew/lib/python3.11/site-packages/dvc_http/__init__.py", line 6, in <module>
    from dvc_objects.fs.base import FileSystem
  File "/opt/homebrew/lib/python3.11/site-packages/dvc_objects/fs/__init__.py", line 5, in <module>
    from . import generic  # noqa: F401
    ^^^^^^^^^^^^^^^^^^^^^
  File "/opt/homebrew/lib/python3.11/site-packages/dvc_objects/fs/generic.py", line 10, in <module>
    from fsspec.callbacks import DEFAULT_CALLBACK
ImportError: cannot import name 'DEFAULT_CALLBACK' from 'fsspec.callbacks' (/opt/homebrew/lib/python3.11/site-packages/fsspec/callbacks.py)
fatal: pathspec 'predictionFromModel/prediction.json.dvc' did not match any files
fatal: pathspec 'predictionFromModel/.gitignore' did not match any files
Traceback (most recent call last):
  File "/opt/homebrew/lib/python3.11/site-packages/dvc/cli/__init__.py", line 210, in main
    cmd = args.func(args)
          ^^^^^^^^^^^^^^^
  File "/opt/homebrew/lib/python3.11/site-packages/dvc/cli/command.py", line 17, in __init__
    from dvc.repo import Repo
  File "/opt/homebrew/lib/python3.11/site-packages/dvc/repo/__init__.py", line 14, in <module>
    from dvc.ignore import DvcIgnoreFilter
  File "/opt/homebrew/lib/python3.11/site-packages/dvc/ignore.py", line 11, in <module>
    from dvc.fs import Schemes, localfs
  File "/opt/homebrew/lib/python3.11/site-packages/dvc/fs/__init__.py", line 4, in <module>
    from dvc_http import HTTPFileSystem, HTTPSFileSystem  # noqa: F401
    ^^^^^^^^^^^^^^^^^^^^^^^^^^^^^^^^^^^^^^^^^^^^^^^^^^^^
  File "/opt/homebrew/lib/python3.11/site-packages/dvc_http/__init__.py", line 6, in <module>
    from dvc_objects.fs.base import FileSystem
  File "/opt/homebrew/lib/python3.11/site-packages/dvc_objects/fs/__init__.py", line 5, in <module>
    from . import generic  # noqa: F401
    ^^^^^^^^^^^^^^^^^^^^^
  File "/opt/homebrew/lib/python3.11/site-packages/dvc_objects/fs/generic.py", line 10, in <module>
    from fsspec.callbacks import DEFAULT_CALLBACK
ImportError: cannot import name 'DEFAULT_CALLBACK' from 'fsspec.callbacks' (/opt/homebrew/lib/python3.11/site-packages/fsspec/callbacks.py)

During handling of the above exception, another exception occurred:

Traceback (most recent call last):
  File "/opt/homebrew/bin/dvc", line 8, in <module>
    sys.exit(main())
             ^^^^^^
  File "/opt/homebrew/lib/python3.11/site-packages/dvc/cli/__init__.py", line 236, in main
    ret = _log_exceptions(exc) or 255
          ^^^^^^^^^^^^^^^^^^^^
  File "/opt/homebrew/lib/python3.11/site-packages/dvc/cli/__init__.py", line 77, in _log_exceptions
    from dvc.fs import AuthError, ConfigError, RemoteMissingDepsError
  File "/opt/homebrew/lib/python3.11/site-packages/dvc/fs/__init__.py", line 4, in <module>
    from dvc_http import HTTPFileSystem, HTTPSFileSystem  # noqa: F401
    ^^^^^^^^^^^^^^^^^^^^^^^^^^^^^^^^^^^^^^^^^^^^^^^^^^^^
  File "/opt/homebrew/lib/python3.11/site-packages/dvc_http/__init__.py", line 6, in <module>
    from dvc_objects.fs.base import FileSystem
  File "/opt/homebrew/lib/python3.11/site-packages/dvc_objects/fs/__init__.py", line 5, in <module>
    from . import generic  # noqa: F401
    ^^^^^^^^^^^^^^^^^^^^^
  File "/opt/homebrew/lib/python3.11/site-packages/dvc_objects/fs/generic.py", line 10, in <module>
    from fsspec.callbacks import DEFAULT_CALLBACK
ImportError: cannot import name 'DEFAULT_CALLBACK' from 'fsspec.callbacks' (/opt/homebrew/lib/python3.11/site-packages/fsspec/callbacks.py)
[32m2024-02-20 14:27:56 +0100[0m - dagster - [34mINFO[0m - __ASSET_JOB - 577499b6-cee4-43b8-bd48-a510617ed10a - versionPrediction - Prediction successfully versioned
[32m2024-02-20 14:27:56 +0100[0m - dagster - [34mDEBUG[0m - __ASSET_JOB - 577499b6-cee4-43b8-bd48-a510617ed10a - 18914 - versionPrediction - STEP_OUTPUT - Yielded output "result" of type "Nothing". (Type check passed).
[32m2024-02-20 14:27:56 +0100[0m - dagster - [34mDEBUG[0m - __ASSET_JOB - 577499b6-cee4-43b8-bd48-a510617ed10a - 18914 - versionPrediction - ASSET_MATERIALIZATION - Materialized value versionPrediction.
[32m2024-02-20 14:27:56 +0100[0m - dagster - [34mDEBUG[0m - __ASSET_JOB - 577499b6-cee4-43b8-bd48-a510617ed10a - 18914 - versionPrediction - STEP_SUCCESS - Finished execution of step "versionPrediction" in 366ms.
