[32m2024-02-18 13:18:52 +0100[0m - dagster - [34mDEBUG[0m - __ASSET_JOB - 9aafd584-0d89-4143-bb65-367583073a95 - 92236 - LOGS_CAPTURED - Started capturing logs in process (pid: 92236).
[32m2024-02-18 13:18:52 +0100[0m - dagster - [34mDEBUG[0m - __ASSET_JOB - 9aafd584-0d89-4143-bb65-367583073a95 - 92236 - versionStockData - STEP_START - Started execution of step "versionStockData".
[32m2024-02-18 13:18:53 +0100[0m - dagster - [34mERROR[0m - [31m__ASSET_JOB - 9aafd584-0d89-4143-bb65-367583073a95 - 92236 - versionStockData - STEP_FAILURE - Execution of step "versionStockData" failed.

dagster._core.errors.DagsterExecutionStepExecutionError: Error occurred while executing op "versionStockData"::

FileNotFoundError: [Errno 2] No such file or directory: 'export'

Stack Trace:
  File "/opt/homebrew/lib/python3.11/site-packages/dagster/_core/execution/plan/utils.py", line 54, in op_execution_error_boundary
    yield
  File "/opt/homebrew/lib/python3.11/site-packages/dagster/_utils/__init__.py", line 467, in iterate_with_context
    next_output = next(iterator)
                  ^^^^^^^^^^^^^^
  File "/opt/homebrew/lib/python3.11/site-packages/dagster/_core/execution/plan/compute_generator.py", line 131, in _coerce_op_compute_fn_to_iterator
    result = invoke_compute_fn(
             ^^^^^^^^^^^^^^^^^^
  File "/opt/homebrew/lib/python3.11/site-packages/dagster/_core/execution/plan/compute_generator.py", line 125, in invoke_compute_fn
    return fn(context, **args_to_pass) if context_arg_provided else fn(**args_to_pass)
           ^^^^^^^^^^^^^^^^^^^^^^^^^^^
  File "/Users/marcelthomas/Development/MLOPS/my-dagster-project/quickstart_etl/assets/prod-pipeline.py", line 51, in versionStockData
    subprocess.run(["export", "AWS_ACCESS_KEY_ID=test"])
  File "/opt/homebrew/Cellar/python@3.11/3.11.7_1/Frameworks/Python.framework/Versions/3.11/lib/python3.11/subprocess.py", line 548, in run
    with Popen(*popenargs, **kwargs) as process:
         ^^^^^^^^^^^^^^^^^^^^^^^^^^^
  File "/opt/homebrew/Cellar/python@3.11/3.11.7_1/Frameworks/Python.framework/Versions/3.11/lib/python3.11/subprocess.py", line 1026, in __init__
    self._execute_child(args, executable, preexec_fn, close_fds,
  File "/opt/homebrew/Cellar/python@3.11/3.11.7_1/Frameworks/Python.framework/Versions/3.11/lib/python3.11/subprocess.py", line 1950, in _execute_child
    raise child_exception_type(errno_num, err_msg, err_filename)
[0m
