[32m2024-02-19 18:25:20 +0100[0m - dagster - [34mDEBUG[0m - all_assets_job - 49bb3f72-ea3a-43e1-8ba8-1b0f813be5a3 - 10904 - LOGS_CAPTURED - Started capturing logs in process (pid: 10904).
[32m2024-02-19 18:25:20 +0100[0m - dagster - [34mDEBUG[0m - all_assets_job - 49bb3f72-ea3a-43e1-8ba8-1b0f813be5a3 - 10904 - trainLudwigModelRegression - STEP_START - Started execution of step "trainLudwigModelRegression".
[32m2024-02-19 18:25:20 +0100[0m - dagster - [34mINFO[0m - all_assets_job - 49bb3f72-ea3a-43e1-8ba8-1b0f813be5a3 - trainLudwigModelRegression - Could Retrieve the Data from the API and store it in S3 accordingly
[32m2024-02-19 18:25:22 +0100[0m - dagster - [34mERROR[0m - [31mall_assets_job - 49bb3f72-ea3a-43e1-8ba8-1b0f813be5a3 - 10904 - trainLudwigModelRegression - STEP_FAILURE - Execution of step "trainLudwigModelRegression" failed.

dagster._core.errors.DagsterExecutionStepExecutionError: Error occurred while executing op "trainLudwigModelRegression"::

RuntimeError: Caught exception during model preprocessing: 'RSI'

Stack Trace:
  File "/opt/homebrew/lib/python3.11/site-packages/dagster/_core/execution/plan/utils.py", line 54, in op_execution_error_boundary
    yield
  File "/opt/homebrew/lib/python3.11/site-packages/dagster/_utils/__init__.py", line 467, in iterate_with_context
    next_output = next(iterator)
                  ^^^^^^^^^^^^^^
  File "/opt/homebrew/lib/python3.11/site-packages/dagster/_core/execution/plan/compute_generator.py", line 131, in _coerce_op_compute_fn_to_iterator
    result = invoke_compute_fn(
             ^^^^^^^^^^^^^^^^^^
  File "/opt/homebrew/lib/python3.11/site-packages/dagster/_core/execution/plan/compute_generator.py", line 125, in invoke_compute_fn
    return fn(context, **args_to_pass) if context_arg_provided else fn(**args_to_pass)
           ^^^^^^^^^^^^^^^^^^^^^^^^^^^
  File "/Users/marcelthomas/Development/MLOPS/my-dagster-project/quickstart_etl/assets/prod-pipeline.py", line 122, in trainLudwigModelRegression
    trainer.train_model()
  File "/Users/marcelthomas/Development/MLOPS/my-dagster-project/quickstart_etl/assets/prod-pipeline.py", line 57, in train_model
    model.train(dataset=data, split=[0.8, 0.1, 0.1], skip_save_processed_input=True)
  File "/opt/homebrew/lib/python3.11/site-packages/ludwig/api.py", line 578, in train
    preprocessed_data = self.preprocess(  # type: ignore[assignment]
                        ^^^^^^^^^^^^^^^^^^^^^^^^^^^^^^^^^^^^^^^^^^^^
  File "/opt/homebrew/lib/python3.11/site-packages/ludwig/api.py", line 1754, in preprocess
    raise RuntimeError(f"Caught exception during model preprocessing: {str(e)}") from e

The above exception was caused by the following exception:
KeyError: 'RSI'

Stack Trace:
  File "/opt/homebrew/lib/python3.11/site-packages/ludwig/api.py", line 1735, in preprocess
    preprocessed_data = preprocess_for_training(
                        ^^^^^^^^^^^^^^^^^^^^^^^^
  File "/opt/homebrew/lib/python3.11/site-packages/ludwig/data/preprocessing.py", line 1997, in preprocess_for_training
    processed = data_format_processor.preprocess_for_training(
                ^^^^^^^^^^^^^^^^^^^^^^^^^^^^^^^^^^^^^^^^^^^^^^
  File "/opt/homebrew/lib/python3.11/site-packages/ludwig/data/preprocessing.py", line 255, in preprocess_for_training
    return _preprocess_df_for_training(
           ^^^^^^^^^^^^^^^^^^^^^^^^^^^^
  File "/opt/homebrew/lib/python3.11/site-packages/ludwig/data/preprocessing.py", line 2206, in _preprocess_df_for_training
    data, training_set_metadata = build_dataset(
                                  ^^^^^^^^^^^^^^
  File "/opt/homebrew/lib/python3.11/site-packages/ludwig/data/preprocessing.py", line 1249, in build_dataset
    synthesized_dataset_cols[col_name] if col_name in synthesized_dataset_cols else dataset_df[col_name]
                                                                                    ~~~~~~~~~~^^^^^^^^^^
  File "/opt/homebrew/lib/python3.11/site-packages/pandas/core/frame.py", line 3893, in __getitem__
    indexer = self.columns.get_loc(key)
              ^^^^^^^^^^^^^^^^^^^^^^^^^
  File "/opt/homebrew/lib/python3.11/site-packages/pandas/core/indexes/base.py", line 3798, in get_loc
    raise KeyError(key) from err

The above exception was caused by the following exception:
KeyError: 'RSI'

Stack Trace:
  File "/opt/homebrew/lib/python3.11/site-packages/pandas/core/indexes/base.py", line 3791, in get_loc
    return self._engine.get_loc(casted_key)
           ^^^^^^^^^^^^^^^^^^^^^^^^^^^^^^^^
  File "index.pyx", line 152, in pandas._libs.index.IndexEngine.get_loc
  File "index.pyx", line 181, in pandas._libs.index.IndexEngine.get_loc
  File "pandas/_libs/hashtable_class_helper.pxi", line 7080, in pandas._libs.hashtable.PyObjectHashTable.get_item
  File "pandas/_libs/hashtable_class_helper.pxi", line 7088, in pandas._libs.hashtable.PyObjectHashTable.get_item
[0m
