[32m2024-02-20 13:49:16 +0100[0m - dagster - [34mDEBUG[0m - __ASSET_JOB - baead051-1606-44fe-9e82-7e5c811897d8 - 17103 - LOGS_CAPTURED - Started capturing logs in process (pid: 17103).
[32m2024-02-20 13:49:16 +0100[0m - dagster - [34mDEBUG[0m - __ASSET_JOB - baead051-1606-44fe-9e82-7e5c811897d8 - 17103 - requestToModel - STEP_START - Started execution of step "requestToModel".
[32m2024-02-20 13:49:17 +0100[0m - dagster - [34mINFO[0m - __ASSET_JOB - baead051-1606-44fe-9e82-7e5c811897d8 - requestToModel - Data Extraction complete
[32m2024-02-20 13:49:17 +0100[0m - dagster - [34mINFO[0m - __ASSET_JOB - baead051-1606-44fe-9e82-7e5c811897d8 - requestToModel -         Datum  Er√∂ffnung  Tageshoch  Tagestief  ...      Umsatz  RSI  EMA  Symbol
0  1999-11-01      68.06      71.88      66.31  ...  12824100.0  0.0  0.0    AMZN
1  1999-11-02      69.75      70.00      65.06  ...  13243200.0  0.0  0.0    AMZN
2  1999-11-03      68.19      68.50      65.00  ...  10772100.0  0.0  0.0    AMZN
3  1999-11-04      67.19      67.19      61.00  ...  16759200.0  0.0  0.0    AMZN
4  1999-11-05      64.75      65.50      62.25  ...  11091400.0  0.0  0.0    AMZN

[5 rows x 9 columns]
[32m2024-02-20 13:49:17 +0100[0m - dagster - [34mINFO[0m - __ASSET_JOB - baead051-1606-44fe-9e82-7e5c811897d8 - requestToModel - Status Code: 400, Response: {'error': "Data received does not contain all input features. Missing features: {'Umsatz in Stueck', 'Tageshoch', 'Datum', 'Eroeffnung', 'Umsatz', 'Tagestief'}."}
[32m2024-02-20 13:49:17 +0100[0m - dagster - [34mERROR[0m - [31m__ASSET_JOB - baead051-1606-44fe-9e82-7e5c811897d8 - 17103 - requestToModel - STEP_FAILURE - Execution of step "requestToModel" failed.

dagster._core.errors.DagsterExecutionStepExecutionError: Error occurred while executing op "requestToModel"::

FileNotFoundError: [Errno 2] No such file or directory: 'predictionFromModel/predicition.json'

Stack Trace:
  File "/opt/homebrew/lib/python3.11/site-packages/dagster/_core/execution/plan/utils.py", line 54, in op_execution_error_boundary
    yield
  File "/opt/homebrew/lib/python3.11/site-packages/dagster/_utils/__init__.py", line 467, in iterate_with_context
    next_output = next(iterator)
                  ^^^^^^^^^^^^^^
  File "/opt/homebrew/lib/python3.11/site-packages/dagster/_core/execution/plan/compute_generator.py", line 131, in _coerce_op_compute_fn_to_iterator
    result = invoke_compute_fn(
             ^^^^^^^^^^^^^^^^^^
  File "/opt/homebrew/lib/python3.11/site-packages/dagster/_core/execution/plan/compute_generator.py", line 125, in invoke_compute_fn
    return fn(context, **args_to_pass) if context_arg_provided else fn(**args_to_pass)
           ^^^^^^^^^^^^^^^^^^^^^^^^^^^
  File "/Users/marcelthomas/Development/MLOPS/my-dagster-project/quickstart_etl/assets/prod-pipeline.py", line 322, in requestToModel
    with open('predictionFromModel/predicition.json', 'w') as f:
         ^^^^^^^^^^^^^^^^^^^^^^^^^^^^^^^^^^^^^^^^^^^^^^^^^
[0m
