[32m2024-02-20 19:09:45 +0100[0m - dagster - [34mDEBUG[0m - __ASSET_JOB - b2def4c5-d3b9-48e7-940b-857a6972c2aa - 30148 - LOGS_CAPTURED - Started capturing logs in process (pid: 30148).
[32m2024-02-20 19:09:45 +0100[0m - dagster - [34mDEBUG[0m - __ASSET_JOB - b2def4c5-d3b9-48e7-940b-857a6972c2aa - 30148 - fetchStockDataFromSource - STEP_START - Started execution of step "fetchStockDataFromSource".
[32m2024-02-20 19:09:49 +0100[0m - dagster - [34mERROR[0m - [31m__ASSET_JOB - b2def4c5-d3b9-48e7-940b-857a6972c2aa - 30148 - fetchStockDataFromSource - STEP_FAILURE - Execution of step "fetchStockDataFromSource" failed.

dagster._core.errors.DagsterExecutionStepExecutionError: Error occurred while executing op "fetchStockDataFromSource"::

KeyError: 'Eroeffnung'

Stack Trace:
  File "/opt/homebrew/lib/python3.11/site-packages/dagster/_core/execution/plan/utils.py", line 54, in op_execution_error_boundary
    yield
  File "/opt/homebrew/lib/python3.11/site-packages/dagster/_utils/__init__.py", line 467, in iterate_with_context
    next_output = next(iterator)
                  ^^^^^^^^^^^^^^
  File "/opt/homebrew/lib/python3.11/site-packages/dagster/_core/execution/plan/compute_generator.py", line 131, in _coerce_op_compute_fn_to_iterator
    result = invoke_compute_fn(
             ^^^^^^^^^^^^^^^^^^
  File "/opt/homebrew/lib/python3.11/site-packages/dagster/_core/execution/plan/compute_generator.py", line 125, in invoke_compute_fn
    return fn(context, **args_to_pass) if context_arg_provided else fn(**args_to_pass)
           ^^^^^^^^^^^^^^^^^^^^^^^^^^^
  File "/Users/marcelthomas/Development/MLOPS/my-dagster-project/quickstart_etl/assets/prod-pipeline.py", line 223, in fetchStockDataFromSource
    if neueste_zeile[spalte].iloc[0] == 0:
       ~~~~~~~~~~~~~^^^^^^^^
  File "/opt/homebrew/lib/python3.11/site-packages/pandas/core/frame.py", line 3893, in __getitem__
    indexer = self.columns.get_loc(key)
              ^^^^^^^^^^^^^^^^^^^^^^^^^
  File "/opt/homebrew/lib/python3.11/site-packages/pandas/core/indexes/base.py", line 3798, in get_loc
    raise KeyError(key) from err

The above exception was caused by the following exception:
KeyError: 'Eroeffnung'

Stack Trace:
  File "/opt/homebrew/lib/python3.11/site-packages/pandas/core/indexes/base.py", line 3791, in get_loc
    return self._engine.get_loc(casted_key)
           ^^^^^^^^^^^^^^^^^^^^^^^^^^^^^^^^
  File "index.pyx", line 152, in pandas._libs.index.IndexEngine.get_loc
  File "index.pyx", line 181, in pandas._libs.index.IndexEngine.get_loc
  File "pandas/_libs/hashtable_class_helper.pxi", line 7080, in pandas._libs.hashtable.PyObjectHashTable.get_item
  File "pandas/_libs/hashtable_class_helper.pxi", line 7088, in pandas._libs.hashtable.PyObjectHashTable.get_item
[0m
