[32m2024-03-04 18:19:24 +0100[0m - dagster - [34mDEBUG[0m - __ASSET_JOB - 88bcabc3-f457-49f4-ace4-943b2ab6de04 - 49160 - LOGS_CAPTURED - Started capturing logs in process (pid: 49160).
[32m2024-03-04 18:19:24 +0100[0m - dagster - [34mDEBUG[0m - __ASSET_JOB - 88bcabc3-f457-49f4-ace4-943b2ab6de04 - 49160 - monitoringAndReporting - STEP_START - Started execution of step "monitoringAndReporting".
[32m2024-03-04 18:19:26 +0100[0m - dagster - [34mERROR[0m - [31m__ASSET_JOB - 88bcabc3-f457-49f4-ace4-943b2ab6de04 - 49160 - monitoringAndReporting - STEP_FAILURE - Execution of step "monitoringAndReporting" failed.

dagster._core.errors.DagsterExecutionStepExecutionError: Error occurred while executing op "monitoringAndReporting"::

botocore.exceptions.ClientError: An error occurred (InvalidAccessKeyId) when calling the PutObject operation: The AWS Access Key Id you provided does not exist in our records.

Stack Trace:
  File "/opt/homebrew/lib/python3.11/site-packages/dagster/_core/execution/plan/utils.py", line 54, in op_execution_error_boundary
    yield
  File "/opt/homebrew/lib/python3.11/site-packages/dagster/_utils/__init__.py", line 467, in iterate_with_context
    next_output = next(iterator)
                  ^^^^^^^^^^^^^^
  File "/opt/homebrew/lib/python3.11/site-packages/dagster/_core/execution/plan/compute_generator.py", line 131, in _coerce_op_compute_fn_to_iterator
    result = invoke_compute_fn(
             ^^^^^^^^^^^^^^^^^^
  File "/opt/homebrew/lib/python3.11/site-packages/dagster/_core/execution/plan/compute_generator.py", line 125, in invoke_compute_fn
    return fn(context, **args_to_pass) if context_arg_provided else fn(**args_to_pass)
           ^^^^^^^^^^^^^^^^^^^^^^^^^^^
  File "/Users/marcelthomas/Development/MLOPS/my-dagster-project/quickstart_etl/assets/prod-pipeline.py", line 414, in monitoringAndReporting
    obj.put(Body=open(reportName, 'rb'))
  File "/opt/homebrew/lib/python3.11/site-packages/boto3/resources/factory.py", line 581, in do_action
    response = action(self, *args, **kwargs)
               ^^^^^^^^^^^^^^^^^^^^^^^^^^^^^
  File "/opt/homebrew/lib/python3.11/site-packages/boto3/resources/action.py", line 88, in __call__
    response = getattr(parent.meta.client, operation_name)(*args, **params)
               ^^^^^^^^^^^^^^^^^^^^^^^^^^^^^^^^^^^^^^^^^^^^^^^^^^^^^^^^^^^^
  File "/opt/homebrew/lib/python3.11/site-packages/botocore/client.py", line 553, in _api_call
    return self._make_api_call(operation_name, kwargs)
           ^^^^^^^^^^^^^^^^^^^^^^^^^^^^^^^^^^^^^^^^^^^
  File "/opt/homebrew/lib/python3.11/site-packages/botocore/client.py", line 1009, in _make_api_call
    raise error_class(parsed_response, operation_name)
[0m
