[32m2024-02-18 17:54:57 +0100[0m - dagster - [34mDEBUG[0m - __ASSET_JOB - daf26fc0-f38e-4ee6-a248-b766c27867ce - 4806 - LOGS_CAPTURED - Started capturing logs in process (pid: 4806).
[32m2024-02-18 17:54:57 +0100[0m - dagster - [34mDEBUG[0m - __ASSET_JOB - daf26fc0-f38e-4ee6-a248-b766c27867ce - 4806 - requestToModel - STEP_START - Started execution of step "requestToModel".
[32m2024-02-18 17:54:57 +0100[0m - dagster - [34mINFO[0m - __ASSET_JOB - daf26fc0-f38e-4ee6-a248-b766c27867ce - requestToModel - Data Extraction complete
[32m2024-02-18 17:54:57 +0100[0m - dagster - [34mINFO[0m - __ASSET_JOB - daf26fc0-f38e-4ee6-a248-b766c27867ce - requestToModel -          date  1. open  2. high  3. low  4. close   5. volume  RSI  EMA
0  1999-11-01    68.06    71.88   66.31     69.13  12824100.0  NaN  NaN
1  1999-11-02    69.75    70.00   65.06     66.44  13243200.0  NaN  NaN
2  1999-11-03    68.19    68.50   65.00     65.81  10772100.0  NaN  NaN
3  1999-11-04    67.19    67.19   61.00     63.06  16759200.0  NaN  NaN
4  1999-11-05    64.75    65.50   62.25     64.94  11091400.0  NaN  NaN
[32m2024-02-18 17:54:57 +0100[0m - dagster - [34mERROR[0m - [31m__ASSET_JOB - daf26fc0-f38e-4ee6-a248-b766c27867ce - 4806 - requestToModel - STEP_FAILURE - Execution of step "requestToModel" failed.

dagster._core.errors.DagsterExecutionStepExecutionError: Error occurred while executing op "requestToModel"::

requests.exceptions.JSONDecodeError: Expecting value: line 1 column 1 (char 0)

Stack Trace:
  File "/opt/homebrew/lib/python3.11/site-packages/dagster/_core/execution/plan/utils.py", line 54, in op_execution_error_boundary
    yield
  File "/opt/homebrew/lib/python3.11/site-packages/dagster/_utils/__init__.py", line 467, in iterate_with_context
    next_output = next(iterator)
                  ^^^^^^^^^^^^^^
  File "/opt/homebrew/lib/python3.11/site-packages/dagster/_core/execution/plan/compute_generator.py", line 131, in _coerce_op_compute_fn_to_iterator
    result = invoke_compute_fn(
             ^^^^^^^^^^^^^^^^^^
  File "/opt/homebrew/lib/python3.11/site-packages/dagster/_core/execution/plan/compute_generator.py", line 125, in invoke_compute_fn
    return fn(context, **args_to_pass) if context_arg_provided else fn(**args_to_pass)
           ^^^^^^^^^^^^^^^^^^^^^^^^^^^
  File "/Users/marcelthomas/Development/MLOPS/my-dagster-project/quickstart_etl/assets/prod-pipeline.py", line 321, in requestToModel
    print(f"Status Code: {r.status_code}, Response: {r.json()}")
                                                     ^^^^^^^^
  File "/opt/homebrew/lib/python3.11/site-packages/requests/models.py", line 975, in json
    raise RequestsJSONDecodeError(e.msg, e.doc, e.pos)

The above exception occurred during handling of the following exception:
json.decoder.JSONDecodeError: Expecting value: line 1 column 1 (char 0)

Stack Trace:
  File "/opt/homebrew/lib/python3.11/site-packages/requests/models.py", line 971, in json
    return complexjson.loads(self.text, **kwargs)
           ^^^^^^^^^^^^^^^^^^^^^^^^^^^^^^^^^^^^^^
  File "/opt/homebrew/Cellar/python@3.11/3.11.7_1/Frameworks/Python.framework/Versions/3.11/lib/python3.11/json/__init__.py", line 346, in loads
    return _default_decoder.decode(s)
           ^^^^^^^^^^^^^^^^^^^^^^^^^^
  File "/opt/homebrew/Cellar/python@3.11/3.11.7_1/Frameworks/Python.framework/Versions/3.11/lib/python3.11/json/decoder.py", line 337, in decode
    obj, end = self.raw_decode(s, idx=_w(s, 0).end())
               ^^^^^^^^^^^^^^^^^^^^^^^^^^^^^^^^^^^^^^
  File "/opt/homebrew/Cellar/python@3.11/3.11.7_1/Frameworks/Python.framework/Versions/3.11/lib/python3.11/json/decoder.py", line 355, in raw_decode
    raise JSONDecodeError("Expecting value", s, err.value) from None

The above exception occurred during handling of the following exception:
StopIteration: 0

Stack Trace:
  File "/opt/homebrew/Cellar/python@3.11/3.11.7_1/Frameworks/Python.framework/Versions/3.11/lib/python3.11/json/decoder.py", line 353, in raw_decode
    obj, end = self.scan_once(s, idx)
               ^^^^^^^^^^^^^^^^^^^^^^
[0m
